<?xml version="1.0" ?>
<robot name="partnet_5ca994bd512be485db3bac7ad77ae88e">
	<link name="base"/>
	<link name="link_0">
		<visual name="mouth-8">
			<origin xyz="-0.004069706478648613 0 -0.007451467190511252"/>
			<geometry>
				<mesh filename="textured_objs/new-0.obj" scale="0.18 0.18 0.18"/>
			</geometry>
		</visual>
		<visual name="mouth-8">
			<origin xyz="-0.004069706478648613 0 -0.007451467190511252"/>
			<geometry>
				<mesh filename="textured_objs/new-1.obj" scale="0.18 0.18 0.18"/>
			</geometry>
		</visual>
		<visual name="mouth-8">
			<origin xyz="-0.004069706478648613 0 -0.007451467190511252"/>
			<geometry>
				<mesh filename="textured_objs/original-3.obj" scale="0.18 0.18 0.18"/>
			</geometry>
		</visual>
		<visual name="mouth-8">
			<origin xyz="-0.004069706478648613 0 -0.007451467190511252"/>
			<geometry>
				<mesh filename="textured_objs/original-4.obj" scale="0.18 0.18 0.18"/>
			</geometry>
		</visual>
		<collision>
			<origin xyz="-0.004069706478648613 0 -0.007451467190511252"/>
			<geometry>
				<mesh filename="textured_objs/new-0.obj" scale="0.18 0.18 0.18"/>
			</geometry>
		</collision>
		<collision>
			<origin xyz="-0.004069706478648613 0 -0.007451467190511252"/>
			<geometry>
				<mesh filename="textured_objs/new-1.obj" scale="0.18 0.18 0.18"/>
			</geometry>
		</collision>
		<collision>
			<origin xyz="-0.004069706478648613 0 -0.007451467190511252"/>
			<geometry>
				<mesh filename="textured_objs/original-3.obj" scale="0.18 0.18 0.18"/>
			</geometry>
		</collision>
		<collision>
			<origin xyz="-0.004069706478648613 0 -0.007451467190511252"/>
			<geometry>
				<mesh filename="textured_objs/original-4.obj" scale="0.18 0.18 0.18"/>
			</geometry>
		</collision>
	</link>
	<joint name="fixed_joint_0" type="fixed">
		<origin xyz="0.0 0 0.0"/>
		<child link="link_0"/>
		<parent link="link_0_helper"/>
	</joint>
	<link name="link_1">
		<visual name="body-6">
			<origin xyz="0 0 0"/>
			<geometry>
				<mesh filename="textured_objs/new-5.obj" scale="0.18 0.18 0.18"/>
			</geometry>
		</visual>
		<visual name="body-6">
			<origin xyz="0 0 0"/>
			<geometry>
				<mesh filename="textured_objs/new-4.obj" scale="0.18 0.18 0.18"/>
			</geometry>
		</visual>
		<visual name="lid-7">
			<origin xyz="0 0 0"/>
			<geometry>
				<mesh filename="textured_objs/new-2.obj" scale="0.18 0.18 0.18"/>
			</geometry>
		</visual>
		<collision>
			<origin xyz="0 0 0"/>
			<geometry>
				<mesh filename="textured_objs/new-5.obj" scale="0.18 0.18 0.18"/>
			</geometry>
		</collision>
		<collision>
			<origin xyz="0 0 0"/>
			<geometry>
				<mesh filename="textured_objs/new-4.obj" scale="0.18 0.18 0.18"/>
			</geometry>
		</collision>
		<collision>
			<origin xyz="0 0 0"/>
			<geometry>
				<mesh filename="textured_objs/new-2.obj" scale="0.18 0.18 0.18"/>
			</geometry>
		</collision>
	</link>
	<joint name="fixed_joint_1" type="fixed">
		<origin rpy="1.570796326794897 0 -1.570796326794897" xyz="0 0 0"/>
		<child link="link_1"/>
		<parent link="base"/>
	</joint>
	<link name="link_0_helper"/>
	<joint name="joint_0" type="prismatic">
		<origin xyz="0.004069706478648613 0 0.007451467190511252"/>
		<axis xyz="0 -1 0"/>
		<child link="link_0_helper"/>
		<parent link="link_1"/>
		<limit lower="0" upper="0.015"/>
	</joint>
</robot>
