<?xml version="1.0" ?>
<robot name="partnet_5ca994bd512be485db3bac7ad77ae88e">
	<link name="base"/>
	<link name="link_0">
		<visual name="pressing_lid-4">
			<origin xyz="0.0017510127982153934 0 0.00274114442045887"/>
			<geometry>
				<mesh filename="textured_objs/original-2.obj" scale="0.2 0.2 0.2"/>
			</geometry>
		</visual>
		<visual name="pressing_lid-4">
			<origin xyz="0.0017510127982153934 0 0.00274114442045887"/>
			<geometry>
				<mesh filename="textured_objs/original-3.obj" scale="0.2 0.2 0.2"/>
			</geometry>
		</visual>
		<visual name="pressing_lid-4">
			<origin xyz="0.0017510127982153934 0 0.00274114442045887"/>
			<geometry>
				<mesh filename="textured_objs/original-4.obj" scale="0.2 0.2 0.2"/>
			</geometry>
		</visual>
		<collision>
			<origin xyz="0.0017510127982153934 0 0.00274114442045887"/>
			<geometry>
				<mesh filename="textured_objs/original-2.obj" scale="0.2 0.2 0.2"/>
			</geometry>
		</collision>
		<collision>
			<origin xyz="0.0017510127982153934 0 0.00274114442045887"/>
			<geometry>
				<mesh filename="textured_objs/original-3.obj" scale="0.2 0.2 0.2"/>
			</geometry>
		</collision>
		<collision>
			<origin xyz="0.0017510127982153934 0 0.00274114442045887"/>
			<geometry>
				<mesh filename="textured_objs/original-4.obj" scale="0.2 0.2 0.2"/>
			</geometry>
		</collision>
	</link>
	<joint name="fixed_joint_0" type="fixed">
		<origin xyz="0.0 0 0.0"/>
		<axis xyz="0 1 0"/>
		<child link="link_0"/>
		<parent link="link_0_helper"/>
	</joint>
	<link name="link_1">
		<visual name="base_body-5">
			<origin xyz="0 0 0"/>
			<geometry>
				<mesh filename="textured_objs/original-1.obj" scale="0.2 0.2 0.2"/>
			</geometry>
		</visual>
		<collision>
			<origin xyz="0 0 0"/>
			<geometry>
				<mesh filename="textured_objs/original-1.obj" scale="0.2 0.2 0.2"/>
			</geometry>
		</collision>
	</link>
	<joint name="fixed_joint_1" type="fixed">
		<origin rpy="1.570796326794897 0 -1.570796326794897" xyz="0 0 0"/>
		<child link="link_1"/>
		<parent link="base"/>
	</joint>
	<link name="link_0_helper"/>
	<joint name="joint_0" type="prismatic">
		<origin xyz="-0.0017510127982153934 0 -0.00274114442045887"/>
		<axis xyz="0 -1 0"/>
		<child link="link_0_helper"/>
		<parent link="link_1"/>
		<limit lower="0." upper="0.04"/>
	</joint>
</robot>
