<?xml version="1.0" ?>
<robot name="partnet_u22479855-8ddc-49d6-8559-87b3746aff4b">
	<link name="base"/>
	<link name="link_0">
		<visual name="blade-4">
			<origin xyz="0.06188176700528213 -0.004338400065898895 0.0001239645836926817"/>
			<geometry>
				<mesh filename="textured_objs/original-7.obj" scale="0.2 0.2 0.2"/>
			</geometry>
		</visual>
		<visual name="handle-5">
			<origin xyz="0.06188176700528213 -0.004338400065898895 0.0001239645836926817"/>
			<geometry>
				<mesh filename="textured_objs/original-4.obj" scale="0.2 0.2 0.2"/>
			</geometry>
		</visual>
		<visual name="handle-5">
			<origin xyz="0.06188176700528213 -0.004338400065898895 0.0001239645836926817"/>
			<geometry>
				<mesh filename="textured_objs/original-5.obj" scale="0.2 0.2 0.2"/>
			</geometry>
		</visual>
		<collision>
			<origin xyz="0.06188176700528213 -0.004338400065898895 0.0001239645836926817"/>
			<geometry>
				<mesh filename="textured_objs/original-7.obj" scale="0.2 0.2 0.2"/>
			</geometry>
		</collision>
		<collision>
			<origin xyz="0.06188176700528213 -0.004338400065898895 0.0001239645836926817"/>
			<geometry>
				<mesh filename="textured_objs/original-4.obj" scale="0.2 0.2 0.2"/>
			</geometry>
		</collision>
		<collision>
			<origin xyz="0.06188176700528213 -0.004338400065898895 0.0001239645836926817"/>
			<geometry>
				<mesh filename="textured_objs/original-5.obj" scale="0.2 0.2 0.2"/>
			</geometry>
		</collision>
	</link>
	<joint name="joint_0" type="revolute">
		<origin xyz="-0.06188176700528213 0.004338400065898895 -0.0001239645836926817"/>
		<axis xyz="0 -1 0"/>
		<child link="link_0"/>
		<parent link="link_1"/>
		<limit lower="-0.8230972752405259" upper="-0.0"/>
	</joint>
	<link name="link_1">
		<visual name="screw-3">
			<origin xyz="0 0 0"/>
			<geometry>
				<mesh filename="textured_objs/original-1.obj" scale="0.2 0.2 0.2"/>
			</geometry>
		</visual>
		<visual name="blade-6">
			<origin xyz="0 0 0"/>
			<geometry>
				<mesh filename="textured_objs/original-14.obj" scale="0.2 0.2 0.2"/>
			</geometry>
		</visual>
		<visual name="handle-7">
			<origin xyz="0 0 0"/>
			<geometry>
				<mesh filename="textured_objs/original-11.obj" scale="0.2 0.2 0.2"/>
			</geometry>
		</visual>
		<visual name="handle-7">
			<origin xyz="0 0 0"/>
			<geometry>
				<mesh filename="textured_objs/original-12.obj" scale="0.2 0.2 0.2"/>
			</geometry>
		</visual>
		<collision>
			<origin xyz="0 0 0"/>
			<geometry>
				<mesh filename="textured_objs/original-1.obj" scale="0.2 0.2 0.2"/>
			</geometry>
		</collision>
		<collision>
			<origin xyz="0 0 0"/>
			<geometry>
				<mesh filename="textured_objs/original-14.obj" scale="0.2 0.2 0.2"/>
			</geometry>
		</collision>
		<collision>
			<origin xyz="0 0 0"/>
			<geometry>
				<mesh filename="textured_objs/original-11.obj" scale="0.2 0.2 0.2"/>
			</geometry>
		</collision>
		<collision>
			<origin xyz="0 0 0"/>
			<geometry>
				<mesh filename="textured_objs/original-12.obj" scale="0.2 0.2 0.2"/>
			</geometry>
		</collision>
	</link>
	<joint name="joint_1" type="fixed">
		<origin rpy="1.570796326794897 0 -1.570796326794897" xyz="0 0 0"/>
		<child link="link_1"/>
		<parent link="base"/>
	</joint>
</robot>
