<?xml version="1.0" ?>
<robot name="partnet_a7732257-2737-4c45-aaa2-b2c8a65c5fe8">
	<link name="base"/>
	<link name="link_0">
		<visual name="handle-1">
			<origin xyz="-0.05307537776678295 -0.4973957113119832 -0.31956767807669373"/>
			<geometry>
				<mesh filename="textured_objs/original-3.obj" scale="0.2 0.2 0.2"/>
			</geometry>
		</visual>
		<collision>
			<origin xyz="-0.05307537776678295 -0.4973957113119832 -0.31956767807669373"/>
			<geometry>
				<mesh filename="textured_objs/original-3.obj" scale="0.2 0.2 0.2"/>
			</geometry>
		</collision>
	</link>
	<joint name="joint_0" type="revolute">
		<origin xyz="0.05663692670536441 0.4973957113119832 0.37409080481462603"/>
		<axis xyz="0.9998156523539538 -4.897941595025503e-07 -0.019200554882556953"/>
		<child link="link_0"/>
		<parent link="link_1"/>
		<limit lower="-0.0" upper="0.3490658503988659"/>
	</joint>
	<link name="link_1">
		<visual name="head-3">
			<origin xyz="0.0035615489385814603 0 0.05452312673793228"/>
			<geometry>
				<mesh filename="textured_objs/original-2.obj" scale="0.2 0.2 0.2"/>
			</geometry>
		</visual>
		<visual name="head-3">
			<origin xyz="0.0035615489385814603 0 0.05452312673793228"/>
			<geometry>
				<mesh filename="textured_objs/original-15.obj" scale="0.2 0.2 0.2"/>
			</geometry>
		</visual>
		<visual name="head-3">
			<origin xyz="0.0035615489385814603 0 0.05452312673793228"/>
			<geometry>
				<mesh filename="textured_objs/original-14.obj" scale="0.2 0.2 0.2"/>
			</geometry>
		</visual>
		<visual name="head-3">
			<origin xyz="0.0035615489385814603 0 0.05452312673793228"/>
			<geometry>
				<mesh filename="textured_objs/original-16.obj" scale="0.2 0.2 0.2"/>
			</geometry>
		</visual>
		<visual name="head-3">
			<origin xyz="0.0035615489385814603 0 0.05452312673793228"/>
			<geometry>
				<mesh filename="textured_objs/original-4.obj" scale="0.2 0.2 0.2"/>
			</geometry>
		</visual>
		<visual name="head-3">
			<origin xyz="0.0035615489385814603 0 0.05452312673793228"/>
			<geometry>
				<mesh filename="textured_objs/original-1.obj" scale="0.2 0.2 0.2"/>
			</geometry>
		</visual>
		<visual name="head-3">
			<origin xyz="0.0035615489385814603 0 0.05452312673793228"/>
			<geometry>
				<mesh filename="textured_objs/original-13.obj" scale="0.2 0.2 0.2"/>
			</geometry>
		</visual>
		<visual name="head-3">
			<origin xyz="0.0035615489385814603 0 0.05452312673793228"/>
			<geometry>
				<mesh filename="textured_objs/original-10.obj" scale="0.2 0.2 0.2"/>
			</geometry>
		</visual>
		<visual name="head-3">
			<origin xyz="0.0035615489385814603 0 0.05452312673793228"/>
			<geometry>
				<mesh filename="textured_objs/original-9.obj" scale="0.2 0.2 0.2"/>
			</geometry>
		</visual>
		<visual name="head-3">
			<origin xyz="0.0035615489385814603 0 0.05452312673793228"/>
			<geometry>
				<mesh filename="textured_objs/original-11.obj" scale="0.2 0.2 0.2"/>
			</geometry>
		</visual>
		<visual name="head-3">
			<origin xyz="0.0035615489385814603 0 0.05452312673793228"/>
			<geometry>
				<mesh filename="textured_objs/original-8.obj" scale="0.2 0.2 0.2"/>
			</geometry>
		</visual>
		<visual name="head-3">
			<origin xyz="0.0035615489385814603 0 0.05452312673793228"/>
			<geometry>
				<mesh filename="textured_objs/original-12.obj" scale="0.2 0.2 0.2"/>
			</geometry>
		</visual>
		<collision>
			<origin xyz="0.0035615489385814603 0 0.05452312673793228"/>
			<geometry>
				<mesh filename="textured_objs/original-2.obj" scale="0.2 0.2 0.2"/>
			</geometry>
		</collision>
		<collision>
			<origin xyz="0.0035615489385814603 0 0.05452312673793228"/>
			<geometry>
				<mesh filename="textured_objs/original-15.obj" scale="0.2 0.2 0.2"/>
			</geometry>
		</collision>
		<collision>
			<origin xyz="0.0035615489385814603 0 0.05452312673793228"/>
			<geometry>
				<mesh filename="textured_objs/original-14.obj" scale="0.2 0.2 0.2"/>
			</geometry>
		</collision>
		<collision>
			<origin xyz="0.0035615489385814603 0 0.05452312673793228"/>
			<geometry>
				<mesh filename="textured_objs/original-16.obj" scale="0.2 0.2 0.2"/>
			</geometry>
		</collision>
		<collision>
			<origin xyz="0.0035615489385814603 0 0.05452312673793228"/>
			<geometry>
				<mesh filename="textured_objs/original-4.obj" scale="0.2 0.2 0.2"/>
			</geometry>
		</collision>
		<collision>
			<origin xyz="0.0035615489385814603 0 0.05452312673793228"/>
			<geometry>
				<mesh filename="textured_objs/original-1.obj" scale="0.2 0.2 0.2"/>
			</geometry>
		</collision>
		<collision>
			<origin xyz="0.0035615489385814603 0 0.05452312673793228"/>
			<geometry>
				<mesh filename="textured_objs/original-13.obj" scale="0.2 0.2 0.2"/>
			</geometry>
		</collision>
		<collision>
			<origin xyz="0.0035615489385814603 0 0.05452312673793228"/>
			<geometry>
				<mesh filename="textured_objs/original-10.obj" scale="0.2 0.2 0.2"/>
			</geometry>
		</collision>
		<collision>
			<origin xyz="0.0035615489385814603 0 0.05452312673793228"/>
			<geometry>
				<mesh filename="textured_objs/original-9.obj" scale="0.2 0.2 0.2"/>
			</geometry>
		</collision>
		<collision>
			<origin xyz="0.0035615489385814603 0 0.05452312673793228"/>
			<geometry>
				<mesh filename="textured_objs/original-11.obj" scale="0.2 0.2 0.2"/>
			</geometry>
		</collision>
		<collision>
			<origin xyz="0.0035615489385814603 0 0.05452312673793228"/>
			<geometry>
				<mesh filename="textured_objs/original-8.obj" scale="0.2 0.2 0.2"/>
			</geometry>
		</collision>
		<collision>
			<origin xyz="0.0035615489385814603 0 0.05452312673793228"/>
			<geometry>
				<mesh filename="textured_objs/original-12.obj" scale="0.2 0.2 0.2"/>
			</geometry>
		</collision>
	</link>
	<joint name="joint_1" type="fixed">
		<origin xyz="0.0 0 0.0"/>
		<axis xyz="0 -1 0"/>
		<child link="link_1"/>
		<parent link="link_1_helper"/>
	</joint>
	<link name="link_2">
		<visual name="base_body-4">
			<origin xyz="0 0 0"/>
			<geometry>
				<mesh filename="textured_objs/original-5.obj" scale="0.2 0.2 0.2"/>
			</geometry>
		</visual>
		<visual name="base_body-4">
			<origin xyz="0 0 0"/>
			<geometry>
				<mesh filename="textured_objs/original-6.obj" scale="0.2 0.2 0.2"/>
			</geometry>
		</visual>
		<visual name="base_body-4">
			<origin xyz="0 0 0"/>
			<geometry>
				<mesh filename="textured_objs/original-7.obj" scale="0.2 0.2 0.2"/>
			</geometry>
		</visual>
		<collision>
			<origin xyz="0 0 0"/>
			<geometry>
				<mesh filename="textured_objs/original-5.obj" scale="0.2 0.2 0.2"/>
			</geometry>
		</collision>
		<collision>
			<origin xyz="0 0 0"/>
			<geometry>
				<mesh filename="textured_objs/original-6.obj" scale="0.2 0.2 0.2"/>
			</geometry>
		</collision>
		<collision>
			<origin xyz="0 0 0"/>
			<geometry>
				<mesh filename="textured_objs/original-7.obj" scale="0.2 0.2 0.2"/>
			</geometry>
		</collision>
	</link>
	<joint name="joint_2" type="fixed">
		<origin rpy="1.570796326794897 0 -1.570796326794897" xyz="0 0 0"/>
		<child link="link_2"/>
		<parent link="base"/>
	</joint>
	<link name="link_1_helper"/>
	<joint name="joint_3" type="fixed">
		<origin xyz="-0.0035615489385814603 0 -0.05452312673793228"/>
		<axis xyz="0 1 0"/>
		<child link="link_1_helper"/>
		<parent link="link_2"/>
		<limit lower="0" upper="0.15"/>
	</joint>
</robot>
