<?xml version="1.0" ?>
<robot name="partnet_37b7ae02-618a-4128-ba7d-9a9bd9bd2112">
	<link name="base"/>
	<link name="link_0">
		<visual name="blade-11">
			<origin xyz="0.07557914412182966 0 -0.0003615911096215304"/>
			<geometry>
				<mesh filename="textured_objs/new-1.obj" scale="0.2 0.2 0.2"/>
			</geometry>
		</visual>
		<visual name="handle-12">
			<origin xyz="0.07557914412182966 0 -0.0003615911096215304"/>
			<geometry>
				<mesh filename="textured_objs/new-0.obj" scale="0.2 0.2 0.2"/>
			</geometry>
		</visual>
		<visual name="handle-12">
			<origin xyz="0.07557914412182966 0 -0.0003615911096215304"/>
			<geometry>
				<mesh filename="textured_objs/original-2.obj" scale="0.2 0.2 0.2"/>
			</geometry>
		</visual>
		<visual name="handle-12">
			<origin xyz="0.07557914412182966 0 -0.0003615911096215304"/>
			<geometry>
				<mesh filename="textured_objs/original-1.obj" scale="0.2 0.2 0.2"/>
			</geometry>
		</visual>
		<collision>
			<origin xyz="0.07557914412182966 0 -0.0003615911096215304"/>
			<geometry>
				<mesh filename="textured_objs/new-1.obj" scale="0.2 0.2 0.2"/>
			</geometry>
		</collision>
		<collision>
			<origin xyz="0.07557914412182966 0 -0.0003615911096215304"/>
			<geometry>
				<mesh filename="textured_objs/new-0.obj" scale="0.2 0.2 0.2"/>
			</geometry>
		</collision>
		<collision>
			<origin xyz="0.07557914412182966 0 -0.0003615911096215304"/>
			<geometry>
				<mesh filename="textured_objs/original-2.obj" scale="0.2 0.2 0.2"/>
			</geometry>
		</collision>
		<collision>
			<origin xyz="0.07557914412182966 0 -0.0003615911096215304"/>
			<geometry>
				<mesh filename="textured_objs/original-1.obj" scale="0.2 0.2 0.2"/>
			</geometry>
		</collision>
	</link>
	<joint name="joint_0" type="revolute">
		<origin xyz="-0.07557914412182966 0 0.0003615911096215304"/>
		<axis xyz="0 -1 0"/>
		<child link="link_0"/>
		<parent link="link_1"/>
		<limit lower="-0.050265482457436686" upper="0.722566310325652"/>
	</joint>
	<link name="link_1">
		<visual name="screw-10">
			<origin xyz="0 0 0"/>
			<geometry>
				<mesh filename="textured_objs/original-7.obj" scale="0.2 0.2 0.2"/>
			</geometry>
		</visual>
		<visual name="blade-13">
			<origin xyz="0 0 0"/>
			<geometry>
				<mesh filename="textured_objs/new-3.obj" scale="0.2 0.2 0.2"/>
			</geometry>
		</visual>
		<visual name="handle-14">
			<origin xyz="0 0 0"/>
			<geometry>
				<mesh filename="textured_objs/original-5.obj" scale="0.2 0.2 0.2"/>
			</geometry>
		</visual>
		<visual name="handle-14">
			<origin xyz="0 0 0"/>
			<geometry>
				<mesh filename="textured_objs/new-2.obj" scale="0.2 0.2 0.2"/>
			</geometry>
		</visual>
		<visual name="handle-14">
			<origin xyz="0 0 0"/>
			<geometry>
				<mesh filename="textured_objs/original-4.obj" scale="0.2 0.2 0.2"/>
			</geometry>
		</visual>
		<collision>
			<origin xyz="0 0 0"/>
			<geometry>
				<mesh filename="textured_objs/original-7.obj" scale="0.2 0.2 0.2"/>
			</geometry>
		</collision>
		<collision>
			<origin xyz="0 0 0"/>
			<geometry>
				<mesh filename="textured_objs/new-3.obj" scale="0.2 0.2 0.2"/>
			</geometry>
		</collision>
		<collision>
			<origin xyz="0 0 0"/>
			<geometry>
				<mesh filename="textured_objs/original-5.obj" scale="0.2 0.2 0.2"/>
			</geometry>
		</collision>
		<collision>
			<origin xyz="0 0 0"/>
			<geometry>
				<mesh filename="textured_objs/new-2.obj" scale="0.2 0.2 0.2"/>
			</geometry>
		</collision>
		<collision>
			<origin xyz="0 0 0"/>
			<geometry>
				<mesh filename="textured_objs/original-4.obj" scale="0.2 0.2 0.2"/>
			</geometry>
		</collision>
	</link>
	<joint name="joint_1" type="fixed">
		<origin rpy="1.570796326794897 0 -1.570796326794897" xyz="0 0 0"/>
		<child link="link_1"/>
		<parent link="base"/>
	</joint>
</robot>
