<?xml version="1.0" ?>
<robot name="partnet_e27e2864f9b54ca5bf9a3f8c45e44354">
	<link name="base"/>
	<link name="link_0">
		<visual name="handle-1">
			<origin xyz="-0.006075000000000053 -0.1647496026103216 -0.030895207992299122"/>
			<geometry>
				<mesh filename="textured_objs/original-5.obj" scale="0.2 0.2 0.2"/>
			</geometry>
		</visual>
		<collision>
			<origin xyz="-0.006075000000000053 -0.1647496026103216 -0.030895207992299122"/>
			<geometry>
				<mesh filename="textured_objs/original-5.obj" scale="0.2 0.2 0.2"/>
			</geometry>
		</collision>
	</link>
	<joint name="joint_0" type="revolute">
		<origin xyz="0.0048911701146697 0.1647496026103216 0.03293605396319994"/>
		<axis xyz="1 0 0"/>
		<child link="link_0"/>
		<parent link="link_1"/>
		<limit lower="-0.0" upper="1.0471975511965976"/>
	</joint>
	<link name="link_1">
		<visual name="head-3">
			<origin xyz="-0.001183829885330353 0 0.002040845970900819"/>
			<geometry>
				<mesh filename="textured_objs/original-3.obj" scale="0.2 0.2 0.2"/>
			</geometry>
		</visual>
		<visual name="head-3">
			<origin xyz="-0.001183829885330353 0 0.002040845970900819"/>
			<geometry>
				<mesh filename="textured_objs/original-6.obj" scale="0.2 0.2 0.2"/>
			</geometry>
		</visual>
		<visual name="head-3">
			<origin xyz="-0.001183829885330353 0 0.002040845970900819"/>
			<geometry>
				<mesh filename="textured_objs/original-4.obj" scale="0.2 0.2 0.2"/>
			</geometry>
		</visual>
		<collision>
			<origin xyz="-0.001183829885330353 0 0.002040845970900819"/>
			<geometry>
				<mesh filename="textured_objs/original-3.obj" scale="0.2 0.2 0.2"/>
			</geometry>
		</collision>
		<collision>
			<origin xyz="-0.001183829885330353 0 0.002040845970900819"/>
			<geometry>
				<mesh filename="textured_objs/original-6.obj" scale="0.2 0.2 0.2"/>
			</geometry>
		</collision>
		<collision>
			<origin xyz="-0.001183829885330353 0 0.002040845970900819"/>
			<geometry>
				<mesh filename="textured_objs/original-4.obj" scale="0.2 0.2 0.2"/>
			</geometry>
		</collision>
	</link>
	<joint name="joint_1" type="fixed">
		<origin xyz="0.0 0 0.0"/>
		<!-- <axis xyz="0 0 0"/> -->
		<child link="link_1"/>
		<parent link="link_1_helper"/>
	</joint>
	<link name="link_2">
		<visual name="base_body-4">
			<origin xyz="0 0 0"/>
			<geometry>
				<mesh filename="textured_objs/original-1.obj" scale="0.2 0.2 0.2"/>
			</geometry>
		</visual>
		<collision>
			<origin xyz="0 0 0"/>
			<geometry>
				<mesh filename="textured_objs/original-1.obj" scale="0.2 0.2 0.2"/>
			</geometry>
		</collision>
	</link>
	<joint name="joint_2" type="fixed">
		<origin rpy="1.570796326794897 0 -1.570796326794897" xyz="0 0 0"/>
		<child link="link_2"/>
		<parent link="base"/>
	</joint>
	<link name="link_1_helper"/>
	<joint name="joint_3" type="fixed">
		<origin xyz="0.001183829885330353 0 -0.002040845970900819"/>
		<!-- <axis xyz="0 0 0"/> -->
		<child link="link_1_helper"/>
		<parent link="link_2"/>
		<!-- <limit lower="0" upper="0.020000000000000018"/> -->
	</joint>
</robot>
